<?xml version="1.0"?>
<robot name="my_robot">

    <material name="green"><color rgba="0 0.5 0 1"/> </material>
    <material name="somethingshit"><color rgba="0 0 0.8 1"></color></material>

    <link name="base_link">
        <visual>
            <geometry>
                <box size="0.6 0.4 0.2" />
            </geometry>

            <origin xyz="0 0 0.1" rpy="0 0 0" />
            <material name="green"></material>
        </visual>
    </link>

    <link name ="right_wheel_link">
        <visual>
            <geometry>
                <cylinder radius="0.1" length = "0.05"/>
            </geometry>
            <origin xyz="0 0 0" rpy="1.57 0 0"/>
            <material name="somethingshit"></material>
        </visual>
    </link>

    <link name ="left_wheel_link">
        <visual>
            <geometry>
                <cylinder radius="0.1" length = "0.05"/>
            </geometry>
            <origin xyz="0 0 0" rpy="1.57 0 0"/>
            <material name="somethingshit"></material>
        </visual>
    </link>



    <joint name="base_right_wheel_joint" type="continuous">
        <origin xyz = "-0.15 -0.225 0" rpy = "3.14 0 0"/>
        <parent link="base_link"/>
        <child link="right_wheel_link"/>
        <axis xyz="0 1 0"/>
    </joint>


    <joint name="base_left_wheel_joint" type="continuous">
        <origin xyz = "-0.15 0.225 0" rpy = "3.14 0 0"/>
        <parent link="base_link"/>
        <child link="left_wheel_link"/>
        <axis xyz="0 1 0"/>
    </joint>
    

</robot>